Workbook

Sheet Instructions
A1: Excel Practice Workbook — Weeks 1 & 2
A5: How this workbook is organised
A6: Data | B6: This is your raw dataset — 60 sales transactions. Every practice question refers to this sheet.
A7: Employees | B7: A lookup table of 10 employees (ID, Name, Department, Region, Join Date). Used for VLOOKUP / INDEX-MATCH / XLOOKUP practice.
A8: PriceList | B8: A small lookup table of products and prices. Also used for lookup practice.
A9: Week1_Practice | B9: 20 questions covering Days 1–7: basic functions, IF/AND/OR, references, sort/filter/duplicates, text functions.
A10: Week2_Practice | B10: 18 questions covering Days 8–13: XLOOKUP, VLOOKUP, INDEX+MATCH, SUMIF/SUMIFS, COUNTIF/COUNTIFS, date functions.
A11: Answer_Key | B11: Working formulas for every question, already calculated. Check yourself only after you try — no peeking first!
A13: How to practice
A14: 1. | B14: Open Week1_Practice, type your formula into the yellow 'Your Formula / Answer' cell for each question.
A15: 2. | B15: Once you've answered a section, open Answer_Key and compare your result and formula.
A16: 3. | B16: For Day 5 (sort / filter / remove duplicates) and the mockup tasks, do them directly on a COPY of the Data sheet — right-click the Data tab → Move or Copy → Create a copy.
A17: 4. | B17: XLOOKUP questions: this file was built with INDEX+MATCH formulas in the answer key for compatibility, but try writing the real =XLOOKUP(...) formula yourself in Excel/365 — it's the modern, recommended function.
A18: 5. | B18: Don't just read the answer key — retype every formula yourself. Typing builds the muscle memory.

Sheet Data
A1: OrderID | B1: OrderDate | C1: EmployeeName | D1: Region | E1: Product | F1: Category | G1: UnitPrice | H1: Quantity | I1: TotalSales | J1: CustomerEmail | K1: 0.18 | L1: <- GST rate for Day 4 exercise (K2 formula = I2*$K$1, copy down) | M1: helper | N1: priority
A2: 1001 | B2: 46190 | C2: Priya Singh | D2: South | E2: Laptop | F2: Electronics | G2: 55000 | H2: 9 | I2: =G2*H2 -> 495000 | J2: priya.singh32@gmail.com | K2: =I2*$K$1 -> 89100 | M2: =IF(Data!I2>20000,"big","small") -> big | N2: =IF(AND(H2>10,D2=D7),"priority") -> FALSE | O2: =IF(OR(F2="Electronics",I2>50000),"discount") -> discount | P2: =IF(AND(Data!H2>15,Data!G1<1000),"review","ok") -> ok
A3: 1002 | B3: 46062 | C3: Priya Singh | D3: South | E3: Office Desk | F3: Furniture | G3: 7000 | H3: 3 | I3: =G3*H3 -> 21000 | J3: priya.singh76@yahoo.com | K3: =I3*$K$1 -> 3780 | M3: =IF(Data!I3>20000,"big","small") -> big | N3: =IF(AND(H3>10,D3=D8),"priority") -> FALSE | O3: =IF(OR(F3="Electronics",I3>50000),"discount") -> FALSE | P3: =IF(AND(Data!H3>15,Data!G2<1000),"review","ok") -> ok
A4: 1003 | B4: 46035 | C4: Rahul Sharma | D4: North | E4: Wireless Mouse | F4: Electronics | G4: 500 | H4: 7 | I4: =G4*H4 -> 3500 | J4: rahul.sharma30@outlook.com | K4: =I4*$K$1 -> 630 | M4: =IF(Data!I4>20000,"big","small") -> small | N4: =IF(AND(H4>10,D4=D9),"priority") -> FALSE | O4: =IF(OR(F4="Electronics",I4>50000),"discount") -> discount | P4: =IF(AND(Data!H4>15,Data!G3<1000),"review","ok") -> ok
A5: 1004 | B5: 46181 | C5: Rahul Sharma | D5: North | E5: Office Desk | F5: Furniture | G5: 7000 | H5: 7 | I5: =G5*H5 -> 49000 | J5: rahul.sharma92@outlook.com | K5: =I5*$K$1 -> 8820 | M5: =IF(Data!I5>20000,"big","small") -> big | N5: =IF(AND(H5>10,D5=D10),"priority") -> FALSE | O5: =IF(OR(F5="Electronics",I5>50000),"discount") -> FALSE | P5: =IF(AND(Data!H5>15,Data!G4<1000),"review","ok") -> ok
A6: 1005 | B6: 46206 | C6: Rohan Das | D6: North | E6: Stapler | F6: Stationery | G6: 150 | H6: 8 | I6: =G6*H6 -> 1200 | J6: rohan.das58@outlook.com | K6: =I6*$K$1 -> 216 | M6: =IF(Data!I6>20000,"big","small") -> small | N6: =IF(AND(H6>10,D6=D11),"priority") -> FALSE | O6: =IF(OR(F6="Electronics",I6>50000),"discount") -> FALSE | P6: =IF(AND(Data!H6>15,Data!G5<1000),"review","ok") -> ok
A7: 1006 | B7: 46098 | C7: Rahul Sharma | D7: North | E7: Keyboard | F7: Electronics | G7: 800 | H7: 14 | I7: =G7*H7 -> 11200 | J7: rahul.sharma44@yahoo.com | K7: =I7*$K$1 -> 2016 | M7: =IF(Data!I7>20000,"big","small") -> small | N7: =IF(AND(H7>10,D7=D12),"priority") -> priority | O7: =IF(OR(F7="Electronics",I7>50000),"discount") -> discount | P7: =IF(AND(Data!H7>15,Data!G6<1000),"review","ok") -> ok
A8: 1007 | B8: 46066 | C8: Neha Gupta | D8: West | E8: Pen Set | F8: Stationery | G8: 120 | H8: 4 | I8: =G8*H8 -> 480 | J8: neha.gupta12@yahoo.com | K8: =I8*$K$1 -> 86.4 | M8: =IF(Data!I8>20000,"big","small") -> small | N8: =IF(AND(H8>10,D8=D13),"priority") -> FALSE | O8: =IF(OR(F8="Electronics",I8>50000),"discount") -> FALSE | P8: =IF(AND(Data!H8>15,Data!G7<1000),"review","ok") -> ok
A9: 1008 | B9: 46051 | C9: Anjali Mehta | D9: South | E9: Pen Set | F9: Stationery | G9: 120 | H9: 20 | I9: =G9*H9 -> 2400 | J9: anjali.mehta34@gmail.com | K9: =I9*$K$1 -> 432 | M9: =IF(Data!I9>20000,"big","small") -> small | N9: =IF(AND(H9>10,D9=D14),"priority") -> priority | O9: =IF(OR(F9="Electronics",I9>50000),"discount") -> FALSE | P9: =IF(AND(Data!H9>15,Data!G8<1000),"review","ok") -> review
A10: 1009 | B10: 46213 | C10: Kavita Nair | D10: West | E10: Office Desk | F10: Furniture | G10: 7000 | H10: 4 | I10: =G10*H10 -> 28000 | J10: kavita.nair49@gmail.com | K10: =I10*$K$1 -> 5040 | M10: =IF(Data!I10>20000,"big","small") -> big | N10: =IF(AND(H10>10,D10=D15),"priority") -> FALSE | O10: =IF(OR(F10="Electronics",I10>50000),"discount") -> FALSE | P10: =IF(AND(Data!H10>15,Data!G9<1000),"review","ok") -> ok
A11: 1010 | B11: 46168 | C11: Vikram Rao | D11: North | E11: Pen Set | F11: Stationery | G11: 120 | H11: 19 | I11: =G11*H11 -> 2280 | J11: vikram.rao25@outlook.com | K11: =I11*$K$1 -> 410.4 | M11: =IF(Data!I11>20000,"big","small") -> small | N11: =IF(AND(H11>10,D11=D16),"priority") -> FALSE | O11: =IF(OR(F11="Electronics",I11>50000),"discount") -> FALSE | P11: =IF(AND(Data!H11>15,Data!G10<1000),"review","ok") -> ok
A12: 1011 | B12: 46044 | C12: Rahul Sharma | D12: North | E12: Monitor | F12: Electronics | G12: 9000 | H12: 10 | I12: =G12*H12 -> 90000 | J12: rahul.sharma11@gmail.com | K12: =I12*$K$1 -> 16200 | M12: =IF(Data!I12>20000,"big","small") -> big | N12: =IF(AND(H12>10,D12=D17),"priority") -> FALSE | O12: =IF(OR(F12="Electronics",I12>50000),"discount") -> discount | P12: =IF(AND(Data!H12>15,Data!G11<1000),"review","ok") -> ok
A13: 1012 | B13: 46248 | C13: Priya Singh | D13: South | E13: Stapler | F13: Stationery | G13: 150 | H13: 9 | I13: =G13*H13 -> 1350 | J13: priya.singh59@outlook.com | K13: =I13*$K$1 -> 243 | M13: =IF(Data!I13>20000,"big","small") -> small | N13: =IF(AND(H13>10,D13=D18),"priority") -> FALSE | O13: =IF(OR(F13="Electronics",I13>50000),"discount") -> FALSE | P13: =IF(AND(Data!H13>15,Data!G12<1000),"review","ok") -> ok
... A63: 1004 | B63: 46181 | C63: Rahul Sharma | D63: North | E63: Office Desk | F63: Furniture | G63: 7000 | H63: 7 | I63: =G63*H63 -> 49000 | J63: rahul.sharma92@outlook.com | K63: =I63*$K$1 -> 8820 | M63: =IF(Data!I63>20000,"big","small") -> big | N63: =IF(AND(H63>10,D63=D68),"priority") -> FALSE | O63: =IF(OR(F63="Electronics",I63>50000),"discount") -> FALSE | P63: =IF(AND(Data!H63>15,Data!G62<1000),"review","ok") -> ok

Sheet Sheet1
A1: 1057 | B1: 46175 | C1: Simran Kaur | D1: South | E1: Laptop | F1: Electronics | G1: 55000 | H1: 20 | I1: =G1*H1 -> 1100000 | J1: simran.kaur11@yahoo.com | L1: {=_xlfn.UNIQUE(A1:J62)} -> 1057 | M1: 46175 | N1: Simran Kaur | O1: South | P1: Laptop | Q1: Electronics | R1: 55000 | S1: 20 | T1: 1100000 | U1: simran.kaur11@yahoo.com
A2: 1001 | B2: 46190 | C2: Priya Singh | D2: South | E2: Laptop | F2: Electronics | G2: 55000 | H2: 9 | I2: =G2*H2 -> 495000 | J2: priya.singh32@gmail.com | L2: 1001 | M2: 46190 | N2: Priya Singh | O2: South | P2: Laptop | Q2: Electronics | R2: 55000 | S2: 9 | T2: 495000 | U2: priya.singh32@gmail.com
A3: 1048 | B3: 46193 | C3: Rohan Das | D3: North | E3: Laptop | F3: Electronics | G3: 55000 | H3: 3 | I3: =G3*H3 -> 165000 | J3: rohan.das97@gmail.com | L3: 1048 | M3: 46193 | N3: Rohan Das | O3: North | P3: Laptop | Q3: Electronics | R3: 55000 | S3: 3 | T3: 165000 | U3: rohan.das97@gmail.com
A4: 1036 | B4: 46122 | C4: Kavita Nair | D4: West | E4: Office Desk | F4: Furniture | G4: 7000 | H4: 15 | I4: =G4*H4 -> 105000 | J4: kavita.nair16@gmail.com | L4: 1036 | M4: 46122 | N4: Kavita Nair | O4: West | P4: Office Desk | Q4: Furniture | R4: 7000 | S4: 15 | T4: 105000 | U4: kavita.nair16@gmail.com
A5: 1016 | B5: 46190 | C5: Rohan Das | D5: North | E5: Monitor | F5: Electronics | G5: 9000 | H5: 11 | I5: =G5*H5 -> 99000 | J5: rohan.das99@gmail.com | L5: 1016 | M5: 46190 | N5: Rohan Das | O5: North | P5: Monitor | Q5: Electronics | R5: 9000 | S5: 11 | T5: 99000 | U5: rohan.das99@gmail.com
A6: 1011 | B6: 46044 | C6: Rahul Sharma | D6: North | E6: Monitor | F6: Electronics | G6: 9000 | H6: 10 | I6: =G6*H6 -> 90000 | J6: rahul.sharma11@gmail.com | L6: 1011 | M6: 46044 | N6: Rahul Sharma | O6: North | P6: Monitor | Q6: Electronics | R6: 9000 | S6: 10 | T6: 90000 | U6: rahul.sharma11@gmail.com
A7: 1040 | B7: 46045 | C7: Rohan Das | D7: North | E7: Monitor | F7: Electronics | G7: 9000 | H7: 9 | I7: =G7*H7 -> 81000 | J7: rohan.das86@yahoo.com | L7: 1040 | M7: 46045 | N7: Rohan Das | O7: North | P7: Monitor | Q7: Electronics | R7: 9000 | S7: 9 | T7: 81000 | U7: rohan.das86@yahoo.com
A8: 1059 | B8: 46198 | C8: Anjali Mehta | D8: South | E8: Monitor | F8: Electronics | G8: 9000 | H8: 9 | I8: =G8*H8 -> 81000 | J8: anjali.mehta51@gmail.com | L8: 1059 | M8: 46198 | N8: Anjali Mehta | O8: South | P8: Monitor | Q8: Electronics | R8: 9000 | S8: 9 | T8: 81000 | U8: anjali.mehta51@gmail.com
A9: 1058 | B9: 46195 | C9: Simran Kaur | D9: South | E9: Office Desk | F9: Furniture | G9: 7000 | H9: 11 | I9: =G9*H9 -> 77000 | J9: simran.kaur34@gmail.com | L9: 1058 | M9: 46195 | N9: Simran Kaur | O9: South | P9: Office Desk | Q9: Furniture | R9: 7000 | S9: 11 | T9: 77000 | U9: simran.kaur34@gmail.com
A10: 1020 | B10: 46217 | C10: Rohan Das | D10: North | E10: Office Desk | F10: Furniture | G10: 7000 | H10: 9 | I10: =G10*H10 -> 63000 | J10: rohan.das96@outlook.com | L10: 1020 | M10: 46217 | N10: Rohan Das | O10: North | P10: Office Desk | Q10: Furniture | R10: 7000 | S10: 9 | T10: 63000 | U10: rohan.das96@outlook.com
A11: 1045 | B11: 46113 | C11: Priya Singh | D11: South | E11: Monitor | F11: Electronics | G11: 9000 | H11: 7 | I11: =G11*H11 -> 63000 | J11: priya.singh25@outlook.com | L11: 1045 | M11: 46113 | N11: Priya Singh | O11: South | P11: Monitor | Q11: Electronics | R11: 9000 | S11: 7 | T11: 63000 | U11: priya.singh25@outlook.com
A12: 1047 | B12: 46090 | C12: Priya Singh | D12: South | E12: Office Chair | F12: Furniture | G12: 3500 | H12: 18 | I12: =G12*H12 -> 63000 | J12: priya.singh13@gmail.com | L12: 1047 | M12: 46090 | N12: Priya Singh | O12: South | P12: Office Chair | Q12: Furniture | R12: 3500 | S12: 18 | T12: 63000 | U12: priya.singh13@gmail.com
A13: 1024 | B13: 46124 | C13: Simran Kaur | D13: South | E13: Office Chair | F13: Furniture | G13: 3500 | H13: 17 | I13: =G13*H13 -> 59500 | J13: simran.kaur33@outlook.com | L13: 1024 | M13: 46124 | N13: Simran Kaur | O13: South | P13: Office Chair | Q13: Furniture | R13: 3500 | S13: 17 | T13: 59500 | U13: simran.kaur33@outlook.com
... A60: 1007 | B60: 46066 | C60: Neha Gupta | D60: West | E60: Pen Set | F60: Stationery | G60: 120 | H60: 4 | I60: =G60*H60 -> 480 | J60: neha.gupta12@yahoo.com | L60: 1037 | M60: 46084 | N60: Priya Singh | O60: South | P60: Pen Set | Q60: Stationery | R60: 120 | S60: 1 | T60: 120 | U60: priya.singh76@outlook.com
A61: 1050 | B61: 46042 | C61: Amit Verma | D61: East | E61: Stapler | F61: Stationery | G61: 150 | H61: 1 | I61: =G61*H61 -> 150 | J61: amit.verma50@yahoo.com
A62: 1037 | B62: 46084 | C62: Priya Singh | D62: South | E62: Pen Set | F62: Stationery | G62: 120 | H62: 1 | I62: =G62*H62 -> 120 | J62: priya.singh76@outlook.com

Sheet Employees
A1: EmployeeID | B1: EmployeeName | C1: Department | D1: Region | E1: JoinDate
A2: E001 | B2: Rahul Sharma | C2: Sales | D2: North | E2: 44269
A3: E002 | B3: Priya Singh | C3: Sales | D3: South | E3: 43647
A4: E003 | B4: Amit Verma | C4: Sales | D4: East | E4: 44888
A5: E004 | B5: Neha Gupta | C5: Sales | D5: West | E5: 43839
A6: E005 | B6: Vikram Rao | C6: Sales | D6: North | E6: 45076
A7: E006 | B7: Anjali Mehta | C7: Sales | D7: South | E7: 43355
A8: E007 | B8: Suresh Kumar | C8: Sales | D8: East | E8: 44532
A9: E008 | B9: Kavita Nair | C9: Sales | D9: West | E9: 44609
A10: E009 | B10: Rohan Das | C10: Sales | D10: North | E10: 45390
A11: E010 | B11: Simran Kaur | C11: Sales | D11: South | E11: 43763

Sheet PriceList
A1: Product | B1: Category | C1: UnitPrice
A2: Laptop | B2: Electronics | C2: 55000
A3: Wireless Mouse | B3: Electronics | C3: 500
A4: Keyboard | B4: Electronics | C4: 800
A5: Monitor | B5: Electronics | C5: 9000
A6: Notebook | B6: Stationery | C6: 50
A7: Pen Set | B7: Stationery | C7: 120
A8: Stapler | B8: Stationery | C8: 150
A9: Office Chair | B9: Furniture | C9: 3500
A10: Office Desk | B10: Furniture | C10: 7000

Sheet =
A1: Week 1 Practice — Excel Fundamentals
A2: # | B2: Day | C2: Topic | D2: Question | E2: Your Formula / Answer
A3: 1 | B3: Day 1-2 | C3: SUM / AVERAGE / MIN / MAX / COUNT | D3: Find the total value of all sales (TotalSales column, rows 2-61). | E3: =SUM(Data!I2:I63) -> 3129410
A4: 2 | B4: Day 1-2 | C4: SUM / AVERAGE / MIN / MAX / COUNT | D4: Find the average Quantity ordered across all 60 orders. | E4: =AVERAGE(Data!H39:H63) -> 8.76
A5: 3 | B5: Day 1-2 | C5: SUM / AVERAGE / MIN / MAX / COUNT | D5: Find the smallest (MIN) UnitPrice in the dataset. | E5: =MIN(Data!G39:G63) -> 50
A6: 4 | B6: Day 1-2 | C6: SUM / AVERAGE / MIN / MAX / COUNT | D6: Find the largest (MAX) TotalSales value in a single order. | E6: =MAX(Data!I39:I63) -> 1100000
A7: 5 | B7: Day 1-2 | C7: SUM / AVERAGE / MIN / MAX / COUNT | D7: Count how many orders were placed in total (COUNT of OrderID). | E7: =COUNT(Data!A39:A63) -> 25
A8: 6 | B8: Day 3 | C8: IF / AND / OR | D8: In a helper column next to the data, mark each order 'Big' if TotalSales > 20000, else 'Small'. Write the formula for row 2.
A9: 7 | B9: Day 3 | C9: IF / AND / OR | D9: Mark an order 'Priority' only if Quantity > 10 AND Region = "North" (row 2).
A10: 8 | B10: Day 3 | C10: IF / AND / OR | D10: Mark an order 'Discount' if Category is "Electronics" OR TotalSales > 50000 (row 2).
A11: 9 | B11: Day 4 | C11: Relative vs Absolute references | D11: In cell K1 of Data, put the GST rate 18% (0.18). In K2, write a formula that multiplies I2 by this rate, so it can be copied down to K61 without the K1 reference shifting. (K1 must contain 0.18, formatted as 18%.)
A12: 10 | B12: Day 4 | C12: Relative vs Absolute references | D12: Explain in one line: what's the difference between A1, $A$1 and A$1 when you copy a formula across rows and columns?
A13: 11 | B13: Day 5 | C13: Sort / Filter / Remove Duplicates | D13: On a COPY of the Data sheet: sort the table by TotalSales, highest to lowest.
A14: 12 | B14: Day 5 | C14: Sort / Filter / Remove Duplicates | D14: On a COPY of the Data sheet: apply a filter so only Region = "South" rows are visible.
A15: 13 | B15: Day 5 | C15: Sort / Filter / Remove Duplicates | D15: On a COPY of the Data sheet (rows 2-63 include 2 planted duplicates): use Remove Duplicates on the whole row to clean the table. How many duplicate rows were removed? | E15: 2
A16: 14 | B16: Day 6 | C16: Text functions | D16: Using LEFT, extract the area code / first 3 letters of the Product name in Data!E2. | E16: =LEFT(Data!E2,3) -> Lap
A17: 15 | B17: Day 6 | C17: Text functions | D17: Using RIGHT, extract the last 4 characters of the CustomerEmail in Data!J2. | E17: =RIGHT(Data!J2,4) -> .com
A18: 16 | B18: Day 6 | C18: Text functions | D18: Using FIND + MID, extract just the username part of the email in Data!J2 (everything before the @). | E18: =MID(Data!J2,1,FIND("@",Data!J2)-1) -> priya.singh32 | F18: =MID(Data!J2,1,FIND("@",Data!J2)-1) -> priya.singh32
A19: 17 | B19: Day 6 | C19: Text functions | D19: Using LEN, find how many characters are in the EmployeeName in Data!C2. | E19: =LEN(Data!C2) -> 11
A20: 18 | B20: Day 7 | C20: Revision | D20: How many orders had TotalSales greater than 10,000? | E20: =COUNTIF(Data!I2:I63,">10000") -> 31 | F20: =SUMIF(Data!I2:I63,">10000") -> 3044100 | G20: =COUNTIF(Data!I39:I63,">10000") -> 16
A21: 19 | B21: Day 7 | C21: Revision | D21: What is the average TotalSales for orders in the "Electronics" category only? | E21: =AVERAGEIF(Data!F2:F63,"Electronics",Data!I2:I63) -> 93716 | F21: =AVERAGEIF(Data!F2:F63,"electronics",Data!I2:I63) -> 93716
A22: 20 | B22: Day 7 | C22: Revision | D22: Combine IF + AND: mark an order "Review" if Quantity > 15 AND UnitPrice < 1000 (row 2), else "OK".

Sheet Week2_Practice
A1: Week 2 Practice — Important Excel Functions
A2: # | B2: Day | C2: Topic | D2: Question | E2: Your Formula / Answer
A3: 1 | B3: Day 8 | C3: XLOOKUP | D3: Look up the UnitPrice of "Office Chair" from the PriceList sheet. (Try the real XLOOKUP function in Excel/365 - the answer key uses an INDEX+MATCH equivalent for compatibility: XLOOKUP("Office Chair",PriceList!A2:A10,PriceList!C2:C10) ) | E3: =_xlfn.XLOOKUP(PriceList!A9,PriceList!A2:A10,PriceList!C2:C10) -> 3500
A4: 2 | B4: Day 8 | C4: XLOOKUP | D4: Look up the Department of employee ID "E006" from the Employees sheet. (Excel 365 equivalent: XLOOKUP("E006",Employees!A2:A11,Employees!C2:C11) ) | E4: =_xlfn.XLOOKUP(Employees!A7,Employees!A2:A11,Employees!C2:C11) -> Sales
A5: 3 | B5: Day 9 | C5: VLOOKUP | D5: Using VLOOKUP, find the Category of "Laptop" from PriceList (table is sorted, use exact match). | E5: =VLOOKUP(PriceList!A2,PriceList!A2:C10,2,FALSE) -> Electronics
A6: 4 | B6: Day 9 | C6: VLOOKUP | D6: Using VLOOKUP, find the Region of employee "Priya Singh" from the Employees sheet. | E6: =VLOOKUP(Employees!B3,Employees!B2:E11,3,FALSE) -> South
A7: 5 | B7: Day 10 | C7: INDEX + MATCH | D7: Using INDEX+MATCH, find the JoinDate of employee "Rohan Das". | E7: =INDEX(Employees!E2:E11,MATCH(Employees!B10,Employees!B2:B11,0)) -> 45390
A8: 6 | B8: Day 10 | C8: INDEX + MATCH | D8: Using INDEX+MATCH, find the UnitPrice of "Pen Set" from PriceList. Explain why INDEX+MATCH still works even if you insert a new column to the left of Price. (Unlike VLOOKUP, INDEX/MATCH does not depend on counting columns, so inserting a column does not break it.) | E8: =INDEX(PriceList!C2:C10,MATCH(PriceList!A7,PriceList!A2:A10,0)) -> 120
A9: 7 | B9: Day 11 | C9: SUMIF / SUMIFS | D9: Find the total TotalSales for Region = "North" only. | E9: =SUMIF(Data!D2:D63,"north",Data!I2:I63) -> 879340
A10: 8 | B10: Day 11 | C10: SUMIF / SUMIFS | D10: Find the total TotalSales where Region = "South" AND Category = "Electronics". | E10: =SUMIFS(Data!I2:I63,Data!D2:D63,Data!D39,Data!F2:F63,Data!F39) -> 1777000
A11: 9 | B11: Day 11 | C11: SUMIF / SUMIFS | D11: Find total Quantity sold where UnitPrice is greater than 1000. | E11: =SUMIF(Data!G2:G63,">1000") -> 328000
A12: 10 | B12: Day 12 | C12: COUNTIF / COUNTIFS | D12: Count how many orders belong to "Rahul Sharma". | E12: =COUNTIF(Data!C2:C63,Data!C4) -> 13
A13: 11 | B13: Day 12 | C13: COUNTIF / COUNTIFS | D13: Count how many orders have Region = "East" AND Quantity >= 10. | E13: =COUNTIFS(Data!D2:D63,"east",Data!H2:H63,">=10") -> 4
A14: 12 | B14: Day 12 | C14: COUNTIF / COUNTIFS | D14: Count how many distinct-looking orders have Category = "Furniture". | E14: =COUNTIF(Data!F2:F63,Data!F48) -> 17
A15: 13 | B15: Day 13 | C15: Date functions | D15: In a new cell, return today's date. | E15: =TODAY() -> 46280
A16: 14 | B16: Day 13 | C16: Date functions | D16: Extract just the Year from the OrderDate in Data!B2. | E16: =YEAR(Data!B2) -> 2026
A17: 15 | B17: Day 13 | C17: Date functions | D17: Extract just the Month (as a number) from the OrderDate in Data!B2. | E17: =MONTH(Data!B2) -> 6
A18: 16 | B18: Day 13 | C18: Date functions | D18: Using DATEDIF, calculate how many full years employee "Amit Verma" (JoinDate in Employees!E4) has worked, as of today. | E18: =DATEDIF(Data!B24,TODAY(),"d") -> 93
A19: 17 | B19: Day 13 | C19: Date functions | D19: Using EDATE, find the date exactly 6 months after the OrderDate in Data!B2. | E19: =EDATE(Data!B2,6) -> 46373
A20: 18 | B20: Day 13 | C20: Date functions | D20: Using NETWORKDAYS, find the number of working days between 01-Jan-2026 and the OrderDate in Data!B2. | E20: =NETWORKDAYS(D21,Data!B2) -> 32993

Sheet Answer_Key
A1: Answer Key
A2: # | B2: Day | C2: Topic | D2: Question | E2: Formula / Answer
A3: WEEK 1
A4: 1 | B4: Day 1-2 | C4: SUM / AVERAGE / MIN / MAX / COUNT | D4: Find the total value of all sales (TotalSales column, rows 2-61). | E4: =SUM(Data!I2:I61) -> 3031410
A5: 2 | B5: Day 1-2 | C5: SUM / AVERAGE / MIN / MAX / COUNT | D5: Find the average Quantity ordered across all 60 orders. | E5: =AVERAGE(Data!H2:H61) -> 10.066667
A6: 3 | B6: Day 1-2 | C6: SUM / AVERAGE / MIN / MAX / COUNT | D6: Find the smallest (MIN) UnitPrice in the dataset. | E6: =MIN(Data!G2:G61) -> 50
A7: 4 | B7: Day 1-2 | C7: SUM / AVERAGE / MIN / MAX / COUNT | D7: Find the largest (MAX) TotalSales value in a single order. | E7: =MAX(Data!I2:I61) -> 1100000
A8: 5 | B8: Day 1-2 | C8: SUM / AVERAGE / MIN / MAX / COUNT | D8: Count how many orders were placed in total (COUNT of OrderID). | E8: =COUNT(Data!A2:A61) -> 60
A9: 6 | B9: Day 3 | C9: IF / AND / OR | D9: In a helper column next to the data, mark each order 'Big' if TotalSales > 20000, else 'Small'. Write the formula for row 2. | E9: =IF(Data!I2>20000,"Big","Small") -> Big
A10: 7 | B10: Day 3 | C10: IF / AND / OR | D10: Mark an order 'Priority' only if Quantity > 10 AND Region = "North" (row 2). | E10: =IF(AND(Data!H2>10,Data!D2="North"),"Priority","Normal") -> Normal
A11: 8 | B11: Day 3 | C11: IF / AND / OR | D11: Mark an order 'Discount' if Category is "Electronics" OR TotalSales > 50000 (row 2). | E11: =IF(OR(Data!F2="Electronics",Data!I2>50000),"Discount","No Discount") -> Discount
A12: 9 | B12: Day 4 | C12: Relative vs Absolute references | D12: In cell K1 of Data, put the GST rate 18% (0.18). In K2, write a formula that multiplies I2 by this rate, so it can be copied down to K61 without the K1 reference shifting. (K1 must contain 0.18, formatted as 18%.) | E12: =I2*$K$1 -> 0
A13: 10 | B13: Day 4 | C13: Relative vs Absolute references | D13: Explain in one line: what's the difference between A1, $A$1 and A$1 when you copy a formula across rows and columns? | E13: A1 = fully relative (both row & column shift). $A$1 = fully absolute (nothing shifts). A$1 = mixed - column shifts, row is locked.
A14: 11 | B14: Day 5 | C14: Sort / Filter / Remove Duplicates | D14: On a COPY of the Data sheet: sort the table by TotalSales, highest to lowest. | E14: Data tab -> Sort & Filter -> Sort Largest to Smallest on TotalSales column.
A15: 12 | B15: Day 5 | C15: Sort / Filter / Remove Duplicates | D15: On a COPY of the Data sheet: apply a filter so only Region = "South" rows are visible. | E15: Select table -> Data -> Filter -> Region dropdown -> tick only South.
A16: 13 | B16: Day 5 | C16: Sort / Filter / Remove Duplicates | D16: On a COPY of the Data sheet (rows 2-63 include 2 planted duplicates): use Remove Duplicates on the whole row to clean the table. How many duplicate rows were removed? | E16: 2 duplicate rows removed (rows 62 and 63 are exact copies of row 5).
A17: 14 | B17: Day 6 | C17: Text functions | D17: Using LEFT, extract the area code / first 3 letters of the Product name in Data!E2. | E17: =LEFT(Data!E2,3) -> Lap
A18: 15 | B18: Day 6 | C18: Text functions | D18: Using RIGHT, extract the last 4 characters of the CustomerEmail in Data!J2. | E18: =RIGHT(Data!J2,4) -> .com
A19: 16 | B19: Day 6 | C19: Text functions | D19: Using FIND + MID, extract just the username part of the email in Data!J2 (everything before the @). | E19: =MID(Data!J2,1,FIND("@",Data!J2)-1) -> priya.singh32
A20: 17 | B20: Day 6 | C20: Text functions | D20: Using LEN, find how many characters are in the EmployeeName in Data!C2. | E20: =LEN(Data!C2) -> 11
A21: 18 | B21: Day 7 | C21: Revision | D21: How many orders had TotalSales greater than 10,000? | E21: =COUNTIF(Data!I2:I61,">10000") -> 29
A22: 19 | B22: Day 7 | C22: Revision | D22: What is the average TotalSales for orders in the "Electronics" category only? | E22: =AVERAGEIF(Data!F2:F61,"Electronics",Data!I2:I61) -> 93716
A23: 20 | B23: Day 7 | C23: Revision | D23: Combine IF + AND: mark an order "Review" if Quantity > 15 AND UnitPrice < 1000 (row 2), else "OK". | E23: =IF(AND(Data!H2>15,Data!G2<1000),"Review","OK") -> OK
A24: WEEK 2
A25: 1 | B25: Day 8 | C25: XLOOKUP | D25: Look up the UnitPrice of "Office Chair" from the PriceList sheet. (Try the real XLOOKUP function in Excel/365 - the answer key uses an INDEX+MATCH equivalent for compatibility: XLOOKUP("Office Chair",PriceList!A2:A10,PriceList!C2:C10) ) | E25: =INDEX(PriceList!C2:C10,MATCH("Office Chair",PriceList!A2:A10,0)) -> 3500
A26: 2 | B26: Day 8 | C26: XLOOKUP | D26: Look up the Department of employee ID "E006" from the Employees sheet. (Excel 365 equivalent: XLOOKUP("E006",Employees!A2:A11,Employees!C2:C11) ) | E26: =INDEX(Employees!C2:C11,MATCH("E006",Employees!A2:A11,0)) -> Sales
A27: 3 | B27: Day 9 | C27: VLOOKUP | D27: Using VLOOKUP, find the Category of "Laptop" from PriceList (table is sorted, use exact match). | E27: =VLOOKUP("Laptop",PriceList!A2:C10,2,FALSE()) -> Electronics
A28: 4 | B28: Day 9 | C28: VLOOKUP | D28: Using VLOOKUP, find the Region of employee "Priya Singh" from the Employees sheet. | E28: =VLOOKUP("Priya Singh",Employees!B2:D11,3,FALSE()) -> South
A29: 5 | B29: Day 10 | C29: INDEX + MATCH | D29: Using INDEX+MATCH, find the JoinDate of employee "Rohan Das". | E29: =INDEX(Employees!E2:E11,MATCH("Rohan Das",Employees!B2:B11,0)) -> 45390
A30: 6 | B30: Day 10 | C30: INDEX + MATCH | D30: Using INDEX+MATCH, find the UnitPrice of "Pen Set" from PriceList. Explain why INDEX+MATCH still works even if you insert a new column to the left of Price. (Unlike VLOOKUP, INDEX/MATCH does not depend on counting columns, so inserting a column does not break it.) | E30: =INDEX(PriceList!C2:C10,MATCH("Pen Set",PriceList!A2:A10,0)) -> 120
A31: 7 | B31: Day 11 | C31: SUMIF / SUMIFS | D31: Find the total TotalSales for Region = "North" only. | E31: =SUMIF(Data!D2:D61,"North",Data!I2:I61) -> 781340
A32: 8 | B32: Day 11 | C32: SUMIF / SUMIFS | D32: Find the total TotalSales where Region = "South" AND Category = "Electronics". | E32: =SUMIFS(Data!I2:I61,Data!D2:D61,"South",Data!F2:F61,"Electronics") -> 1777000
A33: 9 | B33: Day 11 | C33: SUMIF / SUMIFS | D33: Find total Quantity sold where UnitPrice is greater than 1000. | E33: =SUMIF(Data!G2:G61,">1000",Data!H2:H61) -> 223
A34: 10 | B34: Day 12 | C34: COUNTIF / COUNTIFS | D34: Count how many orders belong to "Rahul Sharma". | E34: =COUNTIF(Data!C2:C61,"Rahul Sharma") -> 11
A35: 11 | B35: Day 12 | C35: COUNTIF / COUNTIFS | D35: Count how many orders have Region = "East" AND Quantity >= 10. | E35: =COUNTIFS(Data!D2:D61,"East",Data!H2:H61,">=10") -> 4
A36: 12 | B36: Day 12 | C36: COUNTIF / COUNTIFS | D36: Count how many distinct-looking orders have Category = "Furniture". | E36: =COUNTIF(Data!F2:F61,"Furniture") -> 15
A37: 13 | B37: Day 13 | C37: Date functions | D37: In a new cell, return today's date. | E37: =TODAY() -> 46280
A38: 14 | B38: Day 13 | C38: Date functions | D38: Extract just the Year from the OrderDate in Data!B2. | E38: =YEAR(Data!B2) -> 2026
A39: 15 | B39: Day 13 | C39: Date functions | D39: Extract just the Month (as a number) from the OrderDate in Data!B2. | E39: =MONTH(Data!B2) -> 6
A40: 16 | B40: Day 13 | C40: Date functions | D40: Using DATEDIF, calculate how many full years employee "Amit Verma" (JoinDate in Employees!E4) has worked, as of today. | E40: =DATEDIF(Employees!E4,TODAY(),"y") -> 3
...

Sheet Sheet2
A1: 1001 | B1: 46190 | C1: Priya Singh | D1: South | E1: Laptop | F1: Electronics | G1: 55000 | H1: 9 | I1: =G1*H1 -> 495000 | J1: priya.singh32@gmail.com | K1: =I1*$K$1 -> 89100
A2: 1002 | B2: 46062 | C2: Priya Singh | D2: South | E2: Office Desk | F2: Furniture | G2: 7000 | H2: 3 | I2: =G2*H2 -> 21000 | J2: priya.singh76@yahoo.com | K2: =I2*$K$1 -> 3780
A3: 1003 | B3: 46035 | C3: Rahul Sharma | D3: North | E3: Wireless Mouse | F3: Electronics | G3: 500 | H3: 7 | I3: =G3*H3 -> 3500 | J3: rahul.sharma30@outlook.com | K3: =I3*$K$1 -> 630
A4: 1004 | B4: 46181 | C4: Rahul Sharma | D4: North | E4: Office Desk | F4: Furniture | G4: 7000 | H4: 7 | I4: =G4*H4 -> 49000 | J4: rahul.sharma92@outlook.com | K4: =I4*$K$1 -> 8820
A5: 1005 | B5: 46206 | C5: Rohan Das | D5: North | E5: Stapler | F5: Stationery | G5: 150 | H5: 8 | I5: =G5*H5 -> 1200 | J5: rohan.das58@outlook.com | K5: =I5*$K$1 -> 216
A6: 1006 | B6: 46098 | C6: Rahul Sharma | D6: North | E6: Keyboard | F6: Electronics | G6: 800 | H6: 14 | I6: =G6*H6 -> 11200 | J6: rahul.sharma44@yahoo.com | K6: =I6*$K$1 -> 2016
A7: 1007 | B7: 46066 | C7: Neha Gupta | D7: West | E7: Pen Set | F7: Stationery | G7: 120 | H7: 4 | I7: =G7*H7 -> 480 | J7: neha.gupta12@yahoo.com | K7: =I7*$K$1 -> 86.4
A8: 1008 | B8: 46051 | C8: Anjali Mehta | D8: South | E8: Pen Set | F8: Stationery | G8: 120 | H8: 20 | I8: =G8*H8 -> 2400 | J8: anjali.mehta34@gmail.com | K8: =I8*$K$1 -> 432
A9: 1009 | B9: 46213 | C9: Kavita Nair | D9: West | E9: Office Desk | F9: Furniture | G9: 7000 | H9: 4 | I9: =G9*H9 -> 28000 | J9: kavita.nair49@gmail.com | K9: =I9*$K$1 -> 5040
A10: 1010 | B10: 46168 | C10: Vikram Rao | D10: North | E10: Pen Set | F10: Stationery | G10: 120 | H10: 19 | I10: =G10*H10 -> 2280 | J10: vikram.rao25@outlook.com | K10: =I10*$K$1 -> 410.4
A11: 1011 | B11: 46044 | C11: Rahul Sharma | D11: North | E11: Monitor | F11: Electronics | G11: 9000 | H11: 10 | I11: =G11*H11 -> 90000 | J11: rahul.sharma11@gmail.com | K11: =I11*$K$1 -> 16200
A12: 1012 | B12: 46248 | C12: Priya Singh | D12: South | E12: Stapler | F12: Stationery | G12: 150 | H12: 9 | I12: =G12*H12 -> 1350 | J12: priya.singh59@outlook.com | K12: =I12*$K$1 -> 243
... A62: 1004 | B62: 46181 | C62: Rahul Sharma | D62: North | E62: Office Desk | F62: Furniture | G62: 7000 | H62: 7 | I62: =G62*H62 -> 49000 | J62: rahul.sharma92@outlook.com | K62: =I62*$K$1 -> 8820
